2025-03-21 15:20:03,859 ERROR: Exception on /index [POST] [in /home/student/DBWE/myenv/lib/python3.9/site-packages/flask/app.py:1454]
Traceback (most recent call last):
  File "/home/student/DBWE/myenv/lib/python3.9/site-packages/sqlalchemy/engine/base.py", line 1770, in _execute_context
    self.dialect.do_execute(
  File "/home/student/DBWE/myenv/lib/python3.9/site-packages/sqlalchemy/engine/default.py", line 717, in do_execute
    cursor.execute(statement, parameters)
  File "/home/student/DBWE/myenv/lib/python3.9/site-packages/pymysql/cursors.py", line 153, in execute
    result = self._query(query)
  File "/home/student/DBWE/myenv/lib/python3.9/site-packages/pymysql/cursors.py", line 322, in _query
    conn.query(q)
  File "/home/student/DBWE/myenv/lib/python3.9/site-packages/pymysql/connections.py", line 563, in query
    self._affected_rows = self._read_query_result(unbuffered=unbuffered)
  File "/home/student/DBWE/myenv/lib/python3.9/site-packages/pymysql/connections.py", line 825, in _read_query_result
    result.read()
  File "/home/student/DBWE/myenv/lib/python3.9/site-packages/pymysql/connections.py", line 1199, in read
    first_packet = self.connection._read_packet()
  File "/home/student/DBWE/myenv/lib/python3.9/site-packages/pymysql/connections.py", line 775, in _read_packet
    packet.raise_for_error()
  File "/home/student/DBWE/myenv/lib/python3.9/site-packages/pymysql/protocol.py", line 219, in raise_for_error
    err.raise_mysql_exception(self._data)
  File "/home/student/DBWE/myenv/lib/python3.9/site-packages/pymysql/err.py", line 150, in raise_mysql_exception
    raise errorclass(errno, errval)
pymysql.err.DataError: (1406, "Data too long for column 'body' at row 1")

The above exception was the direct cause of the following exception:

Traceback (most recent call last):
  File "/home/student/DBWE/myenv/lib/python3.9/site-packages/flask/app.py", line 2070, in wsgi_app
    response = self.full_dispatch_request()
  File "/home/student/DBWE/myenv/lib/python3.9/site-packages/flask/app.py", line 1515, in full_dispatch_request
    rv = self.handle_user_exception(e)
  File "/home/student/DBWE/myenv/lib/python3.9/site-packages/flask/app.py", line 1513, in full_dispatch_request
    rv = self.dispatch_request()
  File "/home/student/DBWE/myenv/lib/python3.9/site-packages/flask/app.py", line 1499, in dispatch_request
    return self.ensure_sync(self.view_functions[rule.endpoint])(**req.view_args)
  File "/home/student/DBWE/myenv/lib/python3.9/site-packages/flask_login/utils.py", line 272, in decorated_view
    return func(*args, **kwargs)
  File "/home/student/DBWE/app/routes.py", line 24, in index
    db.session.commit()
  File "<string>", line 2, in commit
  File "/home/student/DBWE/myenv/lib/python3.9/site-packages/sqlalchemy/orm/session.py", line 1428, in commit
    self._transaction.commit(_to_root=self.future)
  File "/home/student/DBWE/myenv/lib/python3.9/site-packages/sqlalchemy/orm/session.py", line 829, in commit
    self._prepare_impl()
  File "/home/student/DBWE/myenv/lib/python3.9/site-packages/sqlalchemy/orm/session.py", line 808, in _prepare_impl
    self.session.flush()
  File "/home/student/DBWE/myenv/lib/python3.9/site-packages/sqlalchemy/orm/session.py", line 3298, in flush
    self._flush(objects)
  File "/home/student/DBWE/myenv/lib/python3.9/site-packages/sqlalchemy/orm/session.py", line 3438, in _flush
    transaction.rollback(_capture_exception=True)
  File "/home/student/DBWE/myenv/lib/python3.9/site-packages/sqlalchemy/util/langhelpers.py", line 70, in __exit__
    compat.raise_(
  File "/home/student/DBWE/myenv/lib/python3.9/site-packages/sqlalchemy/util/compat.py", line 207, in raise_
    raise exception
  File "/home/student/DBWE/myenv/lib/python3.9/site-packages/sqlalchemy/orm/session.py", line 3398, in _flush
    flush_context.execute()
  File "/home/student/DBWE/myenv/lib/python3.9/site-packages/sqlalchemy/orm/unitofwork.py", line 456, in execute
    rec.execute(self)
  File "/home/student/DBWE/myenv/lib/python3.9/site-packages/sqlalchemy/orm/unitofwork.py", line 630, in execute
    util.preloaded.orm_persistence.save_obj(
  File "/home/student/DBWE/myenv/lib/python3.9/site-packages/sqlalchemy/orm/persistence.py", line 242, in save_obj
    _emit_insert_statements(
  File "/home/student/DBWE/myenv/lib/python3.9/site-packages/sqlalchemy/orm/persistence.py", line 1219, in _emit_insert_statements
    result = connection._execute_20(
  File "/home/student/DBWE/myenv/lib/python3.9/site-packages/sqlalchemy/engine/base.py", line 1582, in _execute_20
    return meth(self, args_10style, kwargs_10style, execution_options)
  File "/home/student/DBWE/myenv/lib/python3.9/site-packages/sqlalchemy/sql/elements.py", line 323, in _execute_on_connection
    return connection._execute_clauseelement(
  File "/home/student/DBWE/myenv/lib/python3.9/site-packages/sqlalchemy/engine/base.py", line 1451, in _execute_clauseelement
    ret = self._execute_context(
  File "/home/student/DBWE/myenv/lib/python3.9/site-packages/sqlalchemy/engine/base.py", line 1813, in _execute_context
    self._handle_dbapi_exception(
  File "/home/student/DBWE/myenv/lib/python3.9/site-packages/sqlalchemy/engine/base.py", line 1994, in _handle_dbapi_exception
    util.raise_(
  File "/home/student/DBWE/myenv/lib/python3.9/site-packages/sqlalchemy/util/compat.py", line 207, in raise_
    raise exception
  File "/home/student/DBWE/myenv/lib/python3.9/site-packages/sqlalchemy/engine/base.py", line 1770, in _execute_context
    self.dialect.do_execute(
  File "/home/student/DBWE/myenv/lib/python3.9/site-packages/sqlalchemy/engine/default.py", line 717, in do_execute
    cursor.execute(statement, parameters)
  File "/home/student/DBWE/myenv/lib/python3.9/site-packages/pymysql/cursors.py", line 153, in execute
    result = self._query(query)
  File "/home/student/DBWE/myenv/lib/python3.9/site-packages/pymysql/cursors.py", line 322, in _query
    conn.query(q)
  File "/home/student/DBWE/myenv/lib/python3.9/site-packages/pymysql/connections.py", line 563, in query
    self._affected_rows = self._read_query_result(unbuffered=unbuffered)
  File "/home/student/DBWE/myenv/lib/python3.9/site-packages/pymysql/connections.py", line 825, in _read_query_result
    result.read()
  File "/home/student/DBWE/myenv/lib/python3.9/site-packages/pymysql/connections.py", line 1199, in read
    first_packet = self.connection._read_packet()
  File "/home/student/DBWE/myenv/lib/python3.9/site-packages/pymysql/connections.py", line 775, in _read_packet
    packet.raise_for_error()
  File "/home/student/DBWE/myenv/lib/python3.9/site-packages/pymysql/protocol.py", line 219, in raise_for_error
    err.raise_mysql_exception(self._data)
  File "/home/student/DBWE/myenv/lib/python3.9/site-packages/pymysql/err.py", line 150, in raise_mysql_exception
    raise errorclass(errno, errval)
sqlalchemy.exc.DataError: (pymysql.err.DataError) (1406, "Data too long for column 'body' at row 1")
[SQL: INSERT INTO post (body, timestamp, user_id) VALUES (%(body)s, %(timestamp)s, %(user_id)s)]
[parameters: {'body': 'RIz Casimir\r\nReis:\r\nSalzwasser\r\n300 g\tReis, z.B. Langkornreis\r\nButter zum Verfeinern\r\nCurry-Geschnetzeltes:\r\nMandelblättchen, nach Belie ... (73 characters truncated) ... ter oder Bratcrème\r\nSalz, Pfeffer\r\n2 EL\tMehl\r\n2 EL\tButter\r\n1 - 2 EL\tCurry\r\n2 dl\tWasser, kalt\r\n1\tHühnerbouillonwürfel\r\n2,5 dl\tRahm', 'timestamp': datetime.datetime(2025, 3, 21, 14, 20, 3, 845690), 'user_id': 6}]
(Background on this error at: http://sqlalche.me/e/14/9h9h)
